[2025-06-16T21:17:02.030+0000] {local_task_job_runner.py:120} INFO - ::group::Pre task execution logs
[2025-06-16T21:17:02.038+0000] {taskinstance.py:2076} INFO - Dependencies all met for dep_context=non-requeueable deps ti=<TaskInstance: run_dbt.dbt_task_group.my_first_dbt_model.run manual__2025-06-16T21:01:50.549760+00:00 [queued]>
[2025-06-16T21:17:02.040+0000] {taskinstance.py:2076} INFO - Dependencies all met for dep_context=requeueable deps ti=<TaskInstance: run_dbt.dbt_task_group.my_first_dbt_model.run manual__2025-06-16T21:01:50.549760+00:00 [queued]>
[2025-06-16T21:17:02.040+0000] {taskinstance.py:2306} INFO - Starting attempt 2 of 2
[2025-06-16T21:17:02.046+0000] {taskinstance.py:2330} INFO - Executing <Task(DbtRunLocalOperator): dbt_task_group.my_first_dbt_model.run> on 2025-06-16 21:01:50.549760+00:00
[2025-06-16T21:17:02.048+0000] {standard_task_runner.py:63} INFO - Started process 38017 to run task
[2025-06-16T21:17:02.050+0000] {standard_task_runner.py:90} INFO - Running: ['airflow', 'tasks', 'run', 'run_dbt', 'dbt_task_group.my_first_dbt_model.run', 'manual__2025-06-16T21:01:50.549760+00:00', '--job-id', '7', '--raw', '--subdir', 'DAGS_FOLDER/run_dbt.py', '--cfg-path', '/tmp/tmpabwz_ne1']
[2025-06-16T21:17:02.051+0000] {standard_task_runner.py:91} INFO - Job 7: Subtask dbt_task_group.my_first_dbt_model.run
[2025-06-16T21:17:02.070+0000] {task_command.py:426} INFO - Running <TaskInstance: run_dbt.dbt_task_group.my_first_dbt_model.run manual__2025-06-16T21:01:50.549760+00:00 [running]> on host 16b859fa0317
[2025-06-16T21:17:02.096+0000] {taskinstance.py:2648} INFO - Exporting env vars: AIRFLOW_CTX_DAG_OWNER='utdt-td7' AIRFLOW_CTX_DAG_ID='run_dbt' AIRFLOW_CTX_TASK_ID='dbt_task_group.my_first_dbt_model.run' AIRFLOW_CTX_EXECUTION_DATE='2025-06-16T21:01:50.549760+00:00' AIRFLOW_CTX_TRY_NUMBER='2' AIRFLOW_CTX_DAG_RUN_ID='manual__2025-06-16T21:01:50.549760+00:00'
[2025-06-16T21:17:02.097+0000] {taskinstance.py:430} INFO - ::endgroup::
[2025-06-16T21:17:02.693+0000] {local.py:185} INFO - dbtRunner is available. Using dbtRunner for invoking dbt.
[2025-06-16T21:17:02.693+0000] {local.py:302} INFO - Cloning project to writable temp directory /tmp/tmpuimquqsp from /opt/airflow/dbt_tp
[2025-06-16T21:17:02.694+0000] {local.py:313} INFO - Partial parse is enabled and the latest partial parse file is /tmp/cosmos/run_dbt__dbt_task_group/target/partial_parse.msgpack
[2025-06-16T21:17:02.701+0000] {taskinstance.py:441} INFO - ::group::Post task execution logs
[2025-06-16T21:17:02.703+0000] {taskinstance.py:2905} ERROR - Task failed with exception
Traceback (most recent call last):
  File "/usr/local/lib/python3.11/site-packages/airflow/models/taskinstance.py", line 465, in _execute_task
    result = _execute_callable(context=context, **execute_callable_kwargs)
             ^^^^^^^^^^^^^^^^^^^^^^^^^^^^^^^^^^^^^^^^^^^^^^^^^^^^^^^^^^^^^
  File "/usr/local/lib/python3.11/site-packages/airflow/models/taskinstance.py", line 432, in _execute_callable
    return execute_callable(context=context, **execute_callable_kwargs)
           ^^^^^^^^^^^^^^^^^^^^^^^^^^^^^^^^^^^^^^^^^^^^^^^^^^^^^^^^^^^^
  File "/usr/local/lib/python3.11/site-packages/airflow/models/baseoperator.py", line 400, in wrapper
    return func(self, *args, **kwargs)
           ^^^^^^^^^^^^^^^^^^^^^^^^^^^
  File "/usr/local/lib/python3.11/site-packages/cosmos/operators/base.py", line 266, in execute
    self.build_and_run_cmd(context=context, cmd_flags=self.add_cmd_flags())
  File "/usr/local/lib/python3.11/site-packages/cosmos/operators/local.py", line 499, in build_and_run_cmd
    result = self.run_command(cmd=dbt_cmd, env=env, context=context)
             ^^^^^^^^^^^^^^^^^^^^^^^^^^^^^^^^^^^^^^^^^^^^^^^^^^^^^^^
  File "/usr/local/lib/python3.11/site-packages/cosmos/operators/local.py", line 317, in run_command
    with self.profile_config.ensure_profile() as profile_values:
  File "/usr/local/lib/python3.11/contextlib.py", line 137, in __enter__
    return next(self.gen)
           ^^^^^^^^^^^^^^
  File "/usr/local/lib/python3.11/site-packages/cosmos/config.py", line 270, in ensure_profile
    profile_contents = self.profile_mapping.get_profile_file_contents(
                       ^^^^^^^^^^^^^^^^^^^^^^^^^^^^^^^^^^^^^^^^^^^^^^^
  File "/usr/local/lib/python3.11/site-packages/cosmos/profiles/base.py", line 224, in get_profile_file_contents
    profile_vars = self.profile
                   ^^^^^^^^^^^^
  File "/usr/local/lib/python3.11/site-packages/cosmos/profiles/postgres/user_pass.py", line 43, in profile
    **self.mapped_params,
      ^^^^^^^^^^^^^^^^^^
  File "/usr/local/lib/python3.11/site-packages/cosmos/profiles/base.py", line 299, in mapped_params
    mapped_params[dbt_field] = self.get_dbt_value(dbt_field)
                               ^^^^^^^^^^^^^^^^^^^^^^^^^^^^^
  File "/usr/local/lib/python3.11/site-packages/cosmos/profiles/base.py", line 276, in get_dbt_value
    value = self._get_airflow_conn_field(airflow_field)
            ^^^^^^^^^^^^^^^^^^^^^^^^^^^^^^^^^^^^^^^^^^^
  File "/usr/local/lib/python3.11/site-packages/cosmos/profiles/base.py", line 253, in _get_airflow_conn_field
    value = getattr(self.conn, airflow_field, None)
                    ^^^^^^^^^
  File "/usr/local/lib/python3.11/site-packages/cosmos/profiles/base.py", line 127, in conn
    conn = BaseHook.get_connection(self.conn_id)
           ^^^^^^^^^^^^^^^^^^^^^^^^^^^^^^^^^^^^^
  File "/usr/local/lib/python3.11/site-packages/airflow/hooks/base.py", line 83, in get_connection
    conn = Connection.get_connection_from_secrets(conn_id)
           ^^^^^^^^^^^^^^^^^^^^^^^^^^^^^^^^^^^^^^^^^^^^^^^
  File "/usr/local/lib/python3.11/site-packages/airflow/models/connection.py", line 519, in get_connection_from_secrets
    raise AirflowNotFoundException(f"The conn_id `{conn_id}` isn't defined")
airflow.exceptions.AirflowNotFoundException: The conn_id `postgres` isn't defined
[2025-06-16T21:17:02.707+0000] {taskinstance.py:1206} INFO - Marking task as FAILED. dag_id=run_dbt, task_id=dbt_task_group.my_first_dbt_model.run, run_id=manual__2025-06-16T21:01:50.549760+00:00, execution_date=20250616T210150, start_date=20250616T211702, end_date=20250616T211702
[2025-06-16T21:17:02.712+0000] {standard_task_runner.py:110} ERROR - Failed to execute job 7 for task dbt_task_group.my_first_dbt_model.run (The conn_id `postgres` isn't defined; 38017)
[2025-06-16T21:17:02.735+0000] {local_task_job_runner.py:240} INFO - Task exited with return code 1
[2025-06-16T21:17:02.746+0000] {taskinstance.py:3498} INFO - 0 downstream tasks scheduled from follow-on schedule check
[2025-06-16T21:17:02.750+0000] {local_task_job_runner.py:222} INFO - ::endgroup::
